<?xml version="1.0"?>

<!-- 
  Corrected URDF for F1Tenth Gazebo simulation — v2
  
  Changes from v1:
    - body_mass: 3.5 → 5.0 kg (more realistic with all components)
    - Body inertia recalculated for 5.0 kg
    - Tire friction increased: mu1 0.8→1.0, mu2 1.0→1.5 (prevent drifting)
    - Contact softness: kp 100000→50000, kd 10→50 (softer tire contact)
    - max_wheel_torque: 20→10 Nm (prevent wheelspin / oversteer)
    - Wheel damping: 0.01→0.05, friction 0.0→0.01 (reduce free spinning)
    - Hinge damping: 0.1→0.2 (prevent steering oscillation)
  
  Original changes from stock (carried over from v1):
    - Steering limits: ±0.5 → ±0.31 rad (from VESC servo config)
    - Steering velocity: 5.0 → 3.2 rad/s (from throttle_interpolator)
    - Laser position: 0.275 → 0.27 m (matches launch file)
    - max_steer: 0.5 → 0.31 rad
    - PID gains reduced for realistic mass
-->

<robot xmlns:xacro="http://www.ros.org/wiki/xacro" name="racecar">

  <!-- ================================================================== -->
  <!-- Geometric properties                                                -->
  <!-- ================================================================== -->
  <xacro:property name="wheelbase" value="0.25" />
  <xacro:property name="width" value="0.2032" />
  <xacro:property name="height" value="0.1" />
  <xacro:property name="ground_offset" value="0.02" />
  <xacro:property name="wheel_radius" value="0.0508" />
  <xacro:property name="wheel_length" value="0.0381" />
  <xacro:property name="car_name" value="ego_racecar" />

  <!-- Laser: matches static_transform_publisher in launch file -->
  <xacro:property name="laser_distance_from_base_link" value="0.27" />
  <xacro:property name="laser_height" value="0.05" />
  <xacro:property name="laser_radius" value="0.026" />

  <!-- ================================================================== -->
  <!-- Mass properties                                                     -->
  <!-- Realistic weight with all components:                               -->
  <!--   Traxxas Slash 4x4 chassis + motor: ~2.5 kg                       -->
  <!--   Compute (Jetson/NUC):              ~0.5-0.8 kg                   -->
  <!--   LiPo battery:                      ~0.3-0.5 kg                   -->
  <!--   Hokuyo LiDAR + metal riser:        ~0.3 kg                       -->
  <!--   VESC + RealSense + wiring:         ~0.4 kg                       -->
  <!--   Mounting plates, brackets, screws:  ~0.5-1.0 kg                  -->
  <!--   Total: ~4.5-5.5 kg → using 5.0 kg                               -->
  <!-- ================================================================== -->
  <xacro:property name="body_mass" value="5.0" />
  <xacro:property name="wheel_mass" value="0.15" />
  <xacro:property name="hinge_mass" value="0.1" />

  <!-- Steering limits from VESC servo config -->
  <xacro:property name="max_steering_angle" value="0.31" />
  <xacro:property name="max_steering_velocity" value="3.2" />

  <!-- ================================================================== -->
  <!-- Body inertia at 5.0 kg (solid box: 0.25 x 0.2032 x 0.1)           -->
  <!--   ixx = (1/12)*5.0*(0.2032^2 + 0.1^2)   = 0.0215                  -->
  <!--   iyy = (1/12)*5.0*(0.25^2   + 0.1^2)    = 0.0497                  -->
  <!--   izz = (1/12)*5.0*(0.25^2   + 0.2032^2) = 0.0627                  -->
  <!-- ================================================================== -->

  <!-- ================================================================== -->
  <!-- Wheel inertia at 0.15 kg (cylinder r=0.0508, h=0.0381)             -->
  <!--   ixx = iyy = (1/12)*0.15*(3*0.0508^2 + 0.0381^2) = 0.000115      -->
  <!--   izz = (1/2)*0.15*0.0508^2                        = 0.000194      -->
  <!-- ================================================================== -->

  <!-- ================================================================== -->
  <!-- Materials                                                           -->
  <!-- ================================================================== -->
  <material name="black">
    <color rgba="0.2 0.2 0.2 1."/>
  </material>

  <material name="blue">
    <color rgba="0.3 0.57 1. 1."/>
  </material>

  <!-- ================================================================== -->
  <!-- Base link (chassis)                                                 -->
  <!-- ================================================================== -->
  <link name="${car_name}/base_link">
    <visual>
      <origin xyz="${wheelbase/2} 0 ${ground_offset+height/2}"/>
      <geometry>
        <box size="${wheelbase} ${width} ${height}"/>
      </geometry>
      <material name="blue"/>
    </visual>

    <collision>
      <origin xyz="${wheelbase/2} 0 ${ground_offset+height/2}"/>
      <geometry>
        <box size="${wheelbase * 0.8} ${width * 0.8} ${height}"/>
      </geometry>
    </collision>

    <inertial>
      <origin xyz="${wheelbase/2} 0 ${ground_offset+height/2}"/>
      <mass value="${body_mass}"/>
      <inertia ixx="0.0215" ixy="0.0" ixz="0.0"
               iyy="0.0497" iyz="0.0"
               izz="0.0627"/>
    </inertial>
  </link>

  <gazebo reference="${car_name}/base_link">
    <material>Gazebo/Blue</material>
  </gazebo>

  <!-- ================================================================== -->
  <!-- LiDAR (Hokuyo URG)                                                 -->
  <!-- ================================================================== -->
  <joint name="base_to_laser_model" type="fixed">
    <parent link="${car_name}/base_link"/>
    <child link="${car_name}/laser_model"/>
    <origin xyz="${laser_distance_from_base_link} 0 ${ground_offset+height+(laser_height/2)}"/>
  </joint>

  <link name="${car_name}/laser_model">
    <visual>
      <geometry>
        <cylinder radius="${laser_radius}" length="${laser_height}"/>
      </geometry>
      <material name="black"/>
    </visual>
  </link>

  <!-- ================================================================== -->
  <!-- Back left wheel                                                     -->
  <!-- ================================================================== -->
  <joint name="base_to_back_left_wheel" type="continuous">
    <parent link="${car_name}/base_link"/>
    <child link="${car_name}/back_left_wheel"/>
    <origin xyz="0 ${(wheel_length+width)/2} ${wheel_radius}"/>
    <axis xyz="0 1 0"/>
    <limit effort="100.0" velocity="100.0"/>
    <!-- Increased damping + friction to prevent free spinning -->
    <dynamics damping="0.05" friction="0.01"/>
  </joint>

  <link name="${car_name}/back_left_wheel">
    <visual>
      <geometry>
        <cylinder radius="${wheel_radius}" length="${wheel_length}"/>
      </geometry>
      <material name="black"/>
      <origin rpy="${pi/2} 0 0"/>
    </visual>

    <collision>
      <origin rpy="${pi/2} 0 0"/>
      <geometry>
        <cylinder radius="${wheel_radius}" length="${wheel_length}"/>
      </geometry>
    </collision>

    <inertial>
      <origin rpy="${pi/2} 0 0"/>
      <mass value="${wheel_mass}"/>
      <inertia ixx="0.000115" ixy="0.0" ixz="0.0"
               iyy="0.000115" iyz="0.0"
               izz="0.000194"/>
    </inertial>
  </link>

  <!-- Tire friction: tuned for treaded RC tires on smooth indoor floor -->
  <!-- Higher mu prevents drifting; softer kp/kd gives realistic contact -->
  <gazebo reference="${car_name}/back_left_wheel">
    <material>Gazebo/Black</material>
    <mu1>1.0</mu1>
    <mu2>1.5</mu2>
    <kp>50000.0</kp>
    <kd>50.0</kd>
    <minDepth>0.001</minDepth>
  </gazebo>

  <!-- ================================================================== -->
  <!-- Back right wheel                                                    -->
  <!-- ================================================================== -->
  <joint name="base_to_back_right_wheel" type="continuous">
    <parent link="${car_name}/base_link"/>
    <child link="${car_name}/back_right_wheel"/>
    <origin xyz="0 ${-(wheel_length+width)/2} ${wheel_radius}"/>
    <axis xyz="0 1 0"/>
    <limit effort="100.0" velocity="100.0"/>
    <dynamics damping="0.05" friction="0.01"/>
  </joint>

  <link name="${car_name}/back_right_wheel">
    <visual>
      <geometry>
        <cylinder radius="${wheel_radius}" length="${wheel_length}"/>
      </geometry>
      <material name="black"/>
      <origin rpy="${pi/2} 0 0"/>
    </visual>

    <collision>
      <origin rpy="${pi/2} 0 0"/>
      <geometry>
        <cylinder radius="${wheel_radius}" length="${wheel_length}"/>
      </geometry>
    </collision>

    <inertial>
      <origin rpy="${pi/2} 0 0"/>
      <mass value="${wheel_mass}"/>
      <inertia ixx="0.000115" ixy="0.0" ixz="0.0"
               iyy="0.000115" iyz="0.0"
               izz="0.000194"/>
    </inertial>
  </link>

  <gazebo reference="${car_name}/back_right_wheel">
    <material>Gazebo/Black</material>
    <mu1>1.0</mu1>
    <mu2>1.5</mu2>
    <kp>50000.0</kp>
    <kd>50.0</kd>
    <minDepth>0.001</minDepth>
  </gazebo>

  <!-- ================================================================== -->
  <!-- Front left steering hinge + wheel                                   -->
  <!-- ================================================================== -->
  <joint name="base_to_front_left_hinge" type="revolute">
    <parent link="${car_name}/base_link"/>
    <child link="${car_name}/front_left_hinge"/>
    <origin xyz="${wheelbase} ${(wheel_length+width)/2} ${wheel_radius}"/>
    <axis xyz="0 0 1"/>
    <limit lower="-${max_steering_angle}" upper="${max_steering_angle}" effort="10.0" velocity="${max_steering_velocity}"/>
    <!-- Higher damping prevents steering oscillation at lighter mass -->
    <dynamics damping="0.2" friction="0.01"/>
  </joint>

  <link name="${car_name}/front_left_hinge">
    <inertial>
      <mass value="${hinge_mass}"/>
      <inertia ixx="0.001" ixy="0.0" ixz="0.0"
               iyy="0.001" iyz="0.0"
               izz="0.001"/>
    </inertial>
  </link>

  <joint name="front_left_hinge_to_wheel" type="continuous">
    <parent link="${car_name}/front_left_hinge"/>
    <child link="${car_name}/front_left_wheel"/>
    <axis xyz="0 1 0"/>
    <limit effort="100.0" velocity="100.0"/>
    <dynamics damping="0.05" friction="0.01"/>
  </joint>

  <link name="${car_name}/front_left_wheel">
    <visual>
      <geometry>
        <cylinder radius="${wheel_radius}" length="${wheel_length}"/>
      </geometry>
      <material name="black"/>
      <origin rpy="${pi/2} 0 0"/>
    </visual>

    <collision>
      <origin rpy="${pi/2} 0 0"/>
      <geometry>
        <cylinder radius="${wheel_radius}" length="${wheel_length}"/>
      </geometry>
    </collision>

    <inertial>
      <origin rpy="${pi/2} 0 0"/>
      <mass value="${wheel_mass}"/>
      <inertia ixx="0.000115" ixy="0.0" ixz="0.0"
               iyy="0.000115" iyz="0.0"
               izz="0.000194"/>
    </inertial>
  </link>

  <gazebo reference="${car_name}/front_left_wheel">
    <material>Gazebo/Black</material>
    <mu1>1.0</mu1>
    <mu2>1.5</mu2>
    <kp>50000.0</kp>
    <kd>50.0</kd>
    <minDepth>0.001</minDepth>
  </gazebo>

  <!-- ================================================================== -->
  <!-- Front right steering hinge + wheel                                  -->
  <!-- ================================================================== -->
  <joint name="base_to_front_right_hinge" type="revolute">
    <parent link="${car_name}/base_link"/>
    <child link="${car_name}/front_right_hinge"/>
    <origin xyz="${wheelbase} ${-(wheel_length+width)/2} ${wheel_radius}"/>
    <axis xyz="0 0 1"/>
    <limit lower="-${max_steering_angle}" upper="${max_steering_angle}" effort="10.0" velocity="${max_steering_velocity}"/>
    <dynamics damping="0.2" friction="0.01"/>
  </joint>

  <link name="${car_name}/front_right_hinge">
    <inertial>
      <mass value="${hinge_mass}"/>
      <inertia ixx="0.001" ixy="0.0" ixz="0.0"
               iyy="0.001" iyz="0.0"
               izz="0.001"/>
    </inertial>
  </link>

  <joint name="front_right_hinge_to_wheel" type="continuous">
    <parent link="${car_name}/front_right_hinge"/>
    <child link="${car_name}/front_right_wheel"/>
    <axis xyz="0 1 0"/>
    <limit effort="100.0" velocity="100.0"/>
    <dynamics damping="0.05" friction="0.01"/>
  </joint>

  <link name="${car_name}/front_right_wheel">
    <visual>
      <geometry>
        <cylinder radius="${wheel_radius}" length="${wheel_length}"/>
      </geometry>
      <material name="black"/>
      <origin rpy="${pi/2} 0 0"/>
    </visual>

    <collision>
      <origin rpy="${pi/2} 0 0"/>
      <geometry>
        <cylinder radius="${wheel_radius}" length="${wheel_length}"/>
      </geometry>
    </collision>

    <inertial>
      <origin rpy="${pi/2} 0 0"/>
      <mass value="${wheel_mass}"/>
      <inertia ixx="0.000115" ixy="0.0" ixz="0.0"
               iyy="0.000115" iyz="0.0"
               izz="0.000194"/>
    </inertial>
  </link>

  <gazebo reference="${car_name}/front_right_wheel">
    <material>Gazebo/Black</material>
    <mu1>1.0</mu1>
    <mu2>1.5</mu2>
    <kp>50000.0</kp>
    <kd>50.0</kd>
    <minDepth>0.001</minDepth>
  </gazebo>

  <!-- ================================================================== -->
  <!-- Intel RealSense D435i Camera                                        -->
  <!-- NOTE: Requires ros-foxy-realsense2-description to be installed.     -->
  <!-- Comment out the next two blocks if not available.                    -->
  <!-- ================================================================== -->
  <xacro:include filename="$(find realsense2_description)/urdf/_d435i.urdf.xacro" />

  <xacro:sensor_d435i parent="${car_name}/base_link" name="camera">
    <origin xyz="0.35 0.0 0.15" rpy="0 0 0"/>
  </xacro:sensor_d435i>

  <gazebo reference="camera_link">
    <sensor type="depth" name="camera">
      <always_on>true</always_on>
      <update_rate>30.0</update_rate>
      <camera name="camera">
        <horizontal_fov>1.518</horizontal_fov>
        <image>
          <width>640</width>
          <height>480</height>
          <format>R8G8B8</format>
        </image>
        <clip>
          <near>0.1</near>
          <far>10.0</far>
        </clip>
      </camera>

      <plugin name="camera_plugin" filename="libgazebo_ros_camera.so">
        <ros>
          <namespace>/</namespace>
        </ros>
        <camera_name>camera</camera_name>
        <image_topic_name>color/image_raw</image_topic_name>
        <camera_info_topic_name>color/camera_info</camera_info_topic_name>
        <depth_image_topic_name>depth/image_rect_raw</depth_image_topic_name>
        <depth_image_camera_info_topic_name>depth/camera_info</depth_image_camera_info_topic_name>
        <point_cloud_topic_name>points</point_cloud_topic_name>
        <frame_name>camera_depth_optical_frame</frame_name>
        <min_depth>0.1</min_depth>
        <max_depth>10.0</max_depth>
      </plugin>
    </sensor>
  </gazebo>

  <!-- ================================================================== -->
  <!-- Ackermann drive plugin                                              -->
  <!-- ================================================================== -->
  <gazebo>
    <plugin name="gazebo_ros_ackermann_drive" filename="libgazebo_ros_ackermann_drive.so">
      <ros>
        <remapping>cmd_vel:=cmd_vel</remapping>
        <remapping>odom:=odom</remapping>
      </ros>
      <update_rate>50.0</update_rate>

      <left_steering_joint>base_to_front_left_hinge</left_steering_joint>
      <right_steering_joint>base_to_front_right_hinge</right_steering_joint>

      <rear_left_joint>base_to_back_left_wheel</rear_left_joint>
      <rear_right_joint>base_to_back_right_wheel</rear_right_joint>

      <front_left_joint>front_left_hinge_to_wheel</front_left_joint>
      <front_right_joint>front_right_hinge_to_wheel</front_right_joint>

      <wheel_separation>${width + wheel_length}</wheel_separation>
      <wheel_base>${wheelbase}</wheel_base>

      <wheel_radius>${wheel_radius}</wheel_radius>
      <wheel_diameter>${wheel_radius * 2}</wheel_diameter>

      <max_steer>${max_steering_angle}</max_steer>
      <max_speed>5.0</max_speed>
      <!-- Reduced torque: prevents wheelspin and oversteer -->
      <!-- At 5 kg, 10 Nm on 0.05m wheels = ~40 m/s^2 theoretical max -->
      <!-- Actual acceleration limited by friction to ~2-3 m/s^2 -->
      <max_wheel_torque>10.0</max_wheel_torque>

      <!-- PID gains tuned for 5 kg mass -->
      <linear_velocity_pid_gain>4.0 0.4 0.04</linear_velocity_pid_gain>
      <left_steering_pid_gain>15.0 1.5 0.2</left_steering_pid_gain>
      <right_steering_pid_gain>15.0 1.5 0.2</right_steering_pid_gain>

      <publish_odom>true</publish_odom>
      <publish_odom_tf>true</publish_odom_tf>
      <publish_wheel_tf>true</publish_wheel_tf>
      <odometry_frame>odom</odometry_frame>
      <robot_base_frame>${car_name}/base_link</robot_base_frame>
    </plugin>
  </gazebo>

</robot>